<mujoco model="humanoid">
  <compiler angle="radian"/>

  <option timestep="0.003" integrator="RK4" solver="PGS" iterations="50"/>

  <size nkey="5" nuser_geom="1"/>

  <visual>
    <global offwidth="480"/>
    <map fogend="5"/>
  </visual>

  <default>
    <joint limited="true" armature="1" damping="5"/>
    <geom condim="1" margin="0.001" material="geom" rgba="0.8 0.6 0.4 1"/>
    <general ctrllimited="true" ctrlrange="-0.4 0.4"/>
  </default>

  <asset>
    <texture type="skybox" builtin="gradient" rgb1="0.4 0.5 0.6" rgb2="0 0 0" width="100" height="600"/>
    <texture type="cube" name="texgeom" builtin="flat" mark="cross" rgb1="0.8 0.6 0.4" rgb2="0.8 0.6 0.4" markrgb="1 1 1" width="127" height="762"/>
    <texture type="2d" name="texplane" builtin="checker" rgb1="0 0 0" rgb2="0.8 0.8 0.8" width="100" height="100"/>
    <material name="MatPlane" texture="texplane" texrepeat="60 60" specular="1" shininess="1" reflectance="0.5"/>
    <material name="geom" texture="texgeom" texuniform="true"/>
  </asset>

  <worldbody>
    <geom name="floor" size="20 20 0.125" type="plane" condim="3" friction="1 0.1 0.1" material="MatPlane" rgba="0.8 0.9 0.8 1"/>
    <light pos="0 0 1.3" dir="0 0 -1" directional="true" cutoff="100" exponent="1" diffuse="1 1 1" specular="0.1 0.1 0.1"/>
    <body name="torso" pos="0 0 1.4">
      <joint name="root" type="free" limited="false" actuatorfrclimited="false" armature="0" damping="0"/>
      <geom name="torso1" size="0.07 0.07" quat="0.707107 0.707107 0 0" type="capsule"/>
      <geom name="head" size="0.09" pos="0 0 0.19" user="258"/>
      <geom name="uwaist" size="0.06 0.06" pos="-0.01 0 -0.12" quat="0.707107 0.707107 0 0" type="capsule"/>
      <camera name="track" pos="0 -4 0" quat="0.707107 0.707107 0 0" mode="trackcom"/>
      <body name="lwaist" pos="-0.01 0 -0.26" quat="0.999998 0 -0.002 0">
        <joint name="abdomen_z" pos="0 0 0.065" axis="0 0 1" stiffness="20" range="-0.785398 0.785398" armature="0.02" damping="5"/>
        <joint name="abdomen_y" pos="0 0 0.065" axis="0 1 0" stiffness="10" range="-1.309 0.523599" armature="0.02" damping="5"/>
        <geom name="lwaist" size="0.06 0.06" quat="0.707107 0.707107 0 0" type="capsule"/>
        <body name="pelvis" pos="0 0 -0.165" quat="0.999998 0 -0.002 0">
          <joint name="abdomen_x" pos="0 0 0.1" axis="1 0 0" stiffness="10" range="-0.610865 0.610865" armature="0.02" damping="5"/>
          <geom name="butt" size="0.09 0.07" pos="-0.02 0 0" quat="0.707107 0.707107 0 0" type="capsule"/>
          <body name="right_thigh" pos="0 -0.1 -0.04">
            <joint name="right_hip_x" pos="0 0 0" axis="1 0 0" stiffness="10" range="-0.436332 0.0872665" armature="0.01" damping="5"/>
            <joint name="right_hip_z" pos="0 0 0" axis="0 0 1" stiffness="10" range="-1.0472 0.610865" armature="0.01" damping="5"/>
            <joint name="right_hip_y" pos="0 0 0" axis="0 1 0" stiffness="20" range="-1.91986 0.349066" armature="0.008" damping="5"/>
            <geom name="right_thigh1" size="0.06 0.170074" pos="0 0.005 -0.17" quat="0.999892 0.0147011 0 0" type="capsule"/>
            <body name="right_shin" pos="0 0.01 -0.403">
              <joint name="right_knee" pos="0 0 0.02" axis="0 -1 0" range="-2.79253 -0.0349066" armature="0.006"/>
              <geom name="right_shin1" size="0.049 0.15" pos="0 0 -0.15" type="capsule"/>
              <body name="right_foot" pos="0 0 -0.45">
                <geom name="right_foot" size="0.075" pos="0 0 0.1"/>
              </body>
            </body>
          </body>
          <body name="left_thigh" pos="0 0.1 -0.04">
            <joint name="left_hip_x" pos="0 0 0" axis="-1 0 0" stiffness="10" range="-0.436332 0.0872665" armature="0.01" damping="5"/>
            <joint name="left_hip_z" pos="0 0 0" axis="0 0 -1" stiffness="10" range="-1.0472 0.610865" armature="0.01" damping="5"/>
            <joint name="left_hip_y" pos="0 0 0" axis="0 1 0" stiffness="20" range="-1.91986 0.349066" armature="0.01" damping="5"/>
            <geom name="left_thigh1" size="0.06 0.170074" pos="0 -0.005 -0.17" quat="0.999892 -0.0147011 0 0" type="capsule"/>
            <body name="left_shin" pos="0 -0.01 -0.403">
              <joint name="left_knee" pos="0 0 0.02" axis="0 -1 0" stiffness="1" range="-2.79253 -0.0349066" armature="0.006"/>
              <geom name="left_shin1" size="0.049 0.15" pos="0 0 -0.15" type="capsule"/>
              <body name="left_foot" pos="0 0 -0.45">
                <geom name="left_foot" size="0.075" pos="0 0 0.1"/>
              </body>
            </body>
          </body>
        </body>
      </body>
      <body name="right_upper_arm" pos="0 -0.17 0.06">
        <joint name="right_shoulder1" pos="0 0 0" axis="0.816497 0.408248 0.408248" stiffness="1" range="-1.48353 1.0472" armature="0.0068"/>
        <joint name="right_shoulder2" pos="0 0 0" axis="0 -0.707107 0.707107" stiffness="1" range="-1.48353 1.0472" armature="0.0051"/>
        <geom name="right_uarm1" size="0.04 0.138564" pos="0.08 -0.08 -0.08" quat="0.888074 -0.325058 -0.325058 0" type="capsule"/>
        <body name="right_lower_arm" pos="0.18 -0.18 -0.18">
          <joint name="right_elbow" pos="0 0 0" axis="0 -0.707107 0.707107" range="-1.5708 0.872665" armature="0.0028"/>
          <geom name="right_larm" size="0.031 0.138564" pos="0.09 0.09 0.09" quat="0.459701 0.627963 -0.627963 0" type="capsule"/>
          <geom name="right_hand" size="0.04" pos="0.18 0.18 0.18"/>
          <camera pos="0 0 0"/>
        </body>
      </body>
      <body name="left_upper_arm" pos="0 0.17 0.06">
        <joint name="left_shoulder1" pos="0 0 0" axis="0.816497 -0.408248 0.408248" stiffness="1" range="-1.0472 1.48353" armature="0.0068"/>
        <joint name="left_shoulder2" pos="0 0 0" axis="0 0.707107 0.707107" stiffness="1" range="-1.0472 1.48353" armature="0.0051"/>
        <geom name="left_uarm1" size="0.04 0.138564" pos="0.08 0.08 -0.08" quat="0.888074 0.325058 -0.325058 0" type="capsule"/>
        <body name="left_lower_arm" pos="0.18 0.18 -0.18">
          <joint name="left_elbow" pos="0 0 0" axis="0 -0.707107 -0.707107" range="-1.5708 0.872665" armature="0.0028"/>
          <geom name="left_larm" size="0.031 0.138564" pos="0.09 -0.09 0.09" quat="0.459701 -0.627963 -0.627963 0" type="capsule"/>
          <geom name="left_hand" size="0.04" pos="0.18 -0.18 0.18"/>
        </body>
      </body>
    </body>
  </worldbody>

  <tendon>
    <fixed name="left_hipknee">
      <joint joint="left_hip_y" coef="-1"/>
      <joint joint="left_knee" coef="1"/>
    </fixed>
    <fixed name="right_hipknee">
      <joint joint="right_hip_y" coef="-1"/>
      <joint joint="right_knee" coef="1"/>
    </fixed>
  </tendon>

  <actuator>
    <general name="abdomen_y" joint="abdomen_y" gear="100 0 0 0 0 0"/>
    <general name="abdomen_z" joint="abdomen_z" gear="100 0 0 0 0 0"/>
    <general name="abdomen_x" joint="abdomen_x" gear="100 0 0 0 0 0"/>
    <general name="right_hip_x" joint="right_hip_x" gear="150 0 0 0 0 0"/>
    <general name="right_hip_z" joint="right_hip_z" gear="150 0 0 0 0 0"/>
    <general name="right_hip_y" joint="right_hip_y" gear="300 0 0 0 0 0"/>
    <general name="right_knee" joint="right_knee" gear="200 0 0 0 0 0"/>
    <general name="left_hip_x" joint="left_hip_x" gear="150 0 0 0 0 0"/>
    <general name="left_hip_z" joint="left_hip_z" gear="150 0 0 0 0 0"/>
    <general name="left_hip_y" joint="left_hip_y" gear="300 0 0 0 0 0"/>
    <general name="left_knee" joint="left_knee" gear="200 0 0 0 0 0"/>
    <general name="right_shoulder1" joint="right_shoulder1" gear="25 0 0 0 0 0"/>
    <general name="right_shoulder2" joint="right_shoulder2" gear="25 0 0 0 0 0"/>
    <general name="right_elbow" joint="right_elbow" gear="25 0 0 0 0 0"/>
    <general name="left_shoulder1" joint="left_shoulder1" gear="25 0 0 0 0 0"/>
    <general name="left_shoulder2" joint="left_shoulder2" gear="25 0 0 0 0 0"/>
    <general name="left_elbow" joint="left_elbow" gear="25 0 0 0 0 0"/>
  </actuator>
</mujoco>
